Workbook

Sheet Свод
A1: Свод: оборудование главной подстанции 220 кВ (титулы 3120, 3121, 3123, 3128) по РД — заводские номера и АоРПИ
A2: РД: SMB-46/PTO/6. Electric/1.Последние чертежи/3120 (последняя ревизия каждого СО). Из спецификаций взят только раздел «Оборудование». Дата свода: 28.09.2026.
A3: Открыть папку РД 3120
A5: Лист | B5: Титул | C5: Раздел | D5: Шифр СО / ревизия | E5: Позиций оборудования | F5: Кол-во по СО, шт | G5: Найдено зав. №, шт | H5: Позиций без зав. № | I5: ОК: зав. № + АоРПИ подписан | J5: Зав. № есть, АоРПИ не подписан | K5: Зав. № есть, АоРПИ нет | L5: Позиций без АоРПИ (-) | M5: Главное
A6: 3120 ЭС1 | B6: 3120 | C6: ЭС1 | D6: E19006-CXPP-3120-ЭС1.СО-001 (03-90-1200-44-ЭС.СО-001) / 4А (Спецификация материалов/.doc) | E6: =COUNTA('3120 ЭС1'!B6:B15) | F6: =SUM('3120 ЭС1'!E6:E15) | G6: =SUM('3120 ЭС1'!G6:G15) | H6: =COUNTIF('3120 ЭС1'!L6:L15,"Нет*") | I6: =COUNTIF('3120 ЭС1'!L6:L15,"ОК*") | J6: =COUNTIF('3120 ЭС1'!L6:L15,"*не подписан") | K6: =COUNTIF('3120 ЭС1'!L6:L15,"Зав. № есть, АоРПИ нет") | L6: =COUNTIF('3120 ЭС1'!J6:J15,"-") | M6: КРУЭ 220 кВ: зав. № SGF24012NSD01–04 только в отклонённом RFI 1440, АоРПИ нет; присланные 22.09.2026 документы (TP-0007) — только на ОПН. ТРДН — ОК (477/478). ОПН — 12 зав. № подтверждены паспортами TP-0007 1B, АоРПИ 1248 не подписан и без номеров. ШМУ, токопроводы, ШУ-Д — номеров нет.
A7: 3120 ЭС2 | B7: 3120 | C7: ЭС2 | D7: E19006-CXPP-3120-ЭС2.СО-001 / 4А (.xlsx) | E7: =COUNTA('3120 ЭС2'!B6:B32) | F7: =SUM('3120 ЭС2'!E6:E32) | G7: =SUM('3120 ЭС2'!G6:G32) | H7: =COUNTIF('3120 ЭС2'!L6:L32,"Нет*") | I7: =COUNTIF('3120 ЭС2'!L6:L32,"ОК*") | J7: =COUNTIF('3120 ЭС2'!L6:L32,"*не подписан") | K7: =COUNTIF('3120 ЭС2'!L6:L32,"Зав. № есть, АоРПИ нет") | L7: =COUNTIF('3120 ЭС2'!J6:J32,"-") | M7: КРУ-10 кВ (22 ячейки) и шинные мосты — ОК (АоРПИ 720). ДГР 975/976 — АоРПИ 651 подписан. Разъединители 5, 6 и фильтры (по TQ — трансформаторы ТМГ21-630/10, зав. № 2152742, 2152756) — в АоРПИ 651.
A8: 3120 ЭС3 | B8: 3120 | C8: ЭС3 | D8: E19006-CXPP-3120-ЭС3.СО-001 / 4В (папка «Последняя версия 2026-4-4», .xlsx) | E8: =COUNTA('3120 ЭС3'!B6:B31) | F8: =SUM('3120 ЭС3'!E6:E31) | G8: =SUM('3120 ЭС3'!G6:G31) | H8: =COUNTIF('3120 ЭС3'!L6:L31,"Нет*") | I8: =COUNTIF('3120 ЭС3'!L6:L31,"ОК*") | J8: =COUNTIF('3120 ЭС3'!L6:L31,"*не подписан") | K8: =COUNTIF('3120 ЭС3'!L6:L31,"Зав. № есть, АоРПИ нет") | L8: =COUNTIF('3120 ЭС3'!J6:J31,"-") | M8: ТСН 5842/5843 и ЩСН 297-25 — ОК. ЩПТ 25002/25003 — АоРПИ 816 не подписан и с ошибкой в номере. АКБ, стеллажи, кран, ЯВЗШ, сборки DC, ППУ — номеров нет .
A9: 3120 ЭС4 | B9: 3120 | C9: ЭС4 | D9: E19006-CXPP-3120-ЭС4.СО-001 / 4А (.docm) — проверено 28.09.2026: СО ЭС4 новее 4А в папке РД нет | E9: =COUNTA('3120 ЭС4'!B6:B24) | F9: =SUM('3120 ЭС4'!E6:E24) | G9: =SUM('3120 ЭС4'!G6:G24) | H9: =COUNTIF('3120 ЭС4'!L6:L24,"Нет*") | I9: =COUNTIF('3120 ЭС4'!L6:L24,"ОК*") | J9: =COUNTIF('3120 ЭС4'!L6:L24,"*не подписан") | K9: =COUNTIF('3120 ЭС4'!L6:L24,"Зав. № есть, АоРПИ нет") | L9: =COUNTIF('3120 ЭС4'!J6:J24,"-") | M9: Все шкафы РЗА имеют зав. № (RFI 1556), но АоРПИ 961 не подписан; в нём нет RC15 (10589/21) и дубль 10589/22.
A10: 3120 ЭС5 | B10: 3120 | C10: ЭС5 | D10: E19006-CXPP-3120-ЭС5.СО-001 / 4В (.doc) | E10: =COUNTA('3120 ЭС5'!B6:B7) | F10: =SUM('3120 ЭС5'!E6:E7) | G10: =SUM('3120 ЭС5'!G6:G7) | H10: =COUNTIF('3120 ЭС5'!L6:L7,"Нет*") | I10: =COUNTIF('3120 ЭС5'!L6:L7,"ОК*") | J10: =COUNTIF('3120 ЭС5'!L6:L7,"*не подписан") | K10: =COUNTIF('3120 ЭС5'!L6:L7,"Зав. № есть, АоРПИ нет") | L10: =COUNTIF('3120 ЭС5'!J6:J7,"-") | M10: ШЗВ, ШПС — ни номеров, ни АоРПИ (в папке 742 лежит копия акта ЭС4).
A11: 3120 АСУЭ | B11: 3120 | C11: АСУЭ | D11: 03-50-1200-44-АСУЭ.В4-001 / 4С (pdf, 10.07.2026) — сверено с 4А: состав шкафов и оборудования не изменился; в 4С добавлены обозначения шкафов ATMS, изменены кол-ва кабелей/лотков | E11: =COUNTA('3120 АСУЭ'!B6:B40) | F11: =SUM('3120 АСУЭ'!E6:E40) | G11: =SUM('3120 АСУЭ'!G6:G40) | H11: =COUNTIF('3120 АСУЭ'!L6:L40,"Нет*") | I11: =COUNTIF('3120 АСУЭ'!L6:L40,"ОК*") | J11: =COUNTIF('3120 АСУЭ'!L6:L40,"*не подписан") | K11: =COUNTIF('3120 АСУЭ'!L6:L40,"Зав. № есть, АоРПИ нет") | L11: =COUNTIF('3120 АСУЭ'!J6:J40,"-") | M11: Все 17 шкафов — ОК (АоРПИ 763 подписан). АРМ, антенны, метеостанция — номеров нет.
A12: 3120 АИИСКУЭ | B12: 3120 | C12: АИИСКУЭ | D12: 03-50-1200-44-АИИСКУЭ.В4-001 / 4B (pdf, 13.08.2026) — сверено: шкафы те же (EPFASC, MC); изменены марки счётчиков и ноутбука АРМ инженера | E12: =COUNTA('3120 АИИСКУЭ'!B6:B24) | F12: =SUM('3120 АИИСКУЭ'!E6:E24) | G12: =SUM('3120 АИИСКУЭ'!G6:G24) | H12: =COUNTIF('3120 АИИСКУЭ'!L6:L24,"Нет*") | I12: =COUNTIF('3120 АИИСКУЭ'!L6:L24,"ОК*") | J12: =COUNTIF('3120 АИИСКУЭ'!L6:L24,"*не подписан") | K12: =COUNTIF('3120 АИИСКУЭ'!L6:L24,"Зав. № есть, АоРПИ нет") | L12: =COUNTIF('3120 АИИСКУЭ'!J6:J24,"-") | M12: Шкаф АИИСКУЭ 10589/44 — АоРПИ 781 не подписан, без номера. Шкаф счётчиков 10589/43 — АоРПИ нет. Счётчики СТЭМ — номеров нет.
A13: 3120 ЭО | B13: 3120 | C13: ЭО | D13: E19006-CXPP-3120-ЭО.СО-001 / 4А (.xlsx) | E13: =COUNTA('3120 ЭО'!B6:B31) | F13: =SUM('3120 ЭО'!E6:E31) | G13: =SUM('3120 ЭО'!G6:G31) | H13: =COUNTIF('3120 ЭО'!L6:L31,"Нет*") | I13: =COUNTIF('3120 ЭО'!L6:L31,"ОК*") | J13: =COUNTIF('3120 ЭО'!L6:L31,"*не подписан") | K13: =COUNTIF('3120 ЭО'!L6:L31,"Зав. № есть, АоРПИ нет") | L13: =COUNTIF('3120 ЭО'!J6:J31,"-") | M13: Щиты DY/DS, светильники, ЯТП — номеров нет, АоРПИ на щиты нет; 682, 1070 — не подписаны, 823/859/864 — подписаны.
A14: 3120 СС | B14: 3120 | C14: СС | D14: 03-91-1200-01-СС.СО-001 / 5 (.docx) | E14: =COUNTA('3120 СС'!B6:B8) | F14: =SUM('3120 СС'!E6:E8) | G14: =SUM('3120 СС'!G6:G8) | H14: =COUNTIF('3120 СС'!L6:L8,"Нет*") | I14: =COUNTIF('3120 СС'!L6:L8,"ОК*") | J14: =COUNTIF('3120 СС'!L6:L8,"*не подписан") | K14: =COUNTIF('3120 СС'!L6:L8,"Зав. № есть, АоРПИ нет") | L14: =COUNTIF('3120 СС'!J6:J8,"-") | M14: Слаботочное/автоматика: зав. № и АоРПИ на оборудование отсутствуют; есть только кабельные АоРПИ.
A15: 3121 СС | B15: 3121 | C15: СС | D15: 03-91-1201-44-СС.СО-001 / 5А (.docx) | E15: =COUNTA('3121 СС'!B6:B21) | F15: =SUM('3121 СС'!E6:E21) | G15: =SUM('3121 СС'!G6:G21) | H15: =COUNTIF('3121 СС'!L6:L21,"Нет*") | I15: =COUNTIF('3121 СС'!L6:L21,"ОК*") | J15: =COUNTIF('3121 СС'!L6:L21,"*не подписан") | K15: =COUNTIF('3121 СС'!L6:L21,"Зав. № есть, АоРПИ нет") | L15: =COUNTIF('3121 СС'!J6:J21,"-") | M15: Слаботочное/автоматика: зав. № и АоРПИ на оборудование отсутствуют; есть только кабельные АоРПИ.
A16: 3121 ОС | B16: 3121 | C16: ОС | D16: 03-91-1201-44-ОС.СО-001 / 5 (.xlsx) | E16: =COUNTA('3121 ОС'!B6:B18) | F16: =SUM('3121 ОС'!E6:E18) | G16: =SUM('3121 ОС'!G6:G18) | H16: =COUNTIF('3121 ОС'!L6:L18,"Нет*") | I16: =COUNTIF('3121 ОС'!L6:L18,"ОК*") | J16: =COUNTIF('3121 ОС'!L6:L18,"*не подписан") | K16: =COUNTIF('3121 ОС'!L6:L18,"Зав. № есть, АоРПИ нет") | L16: =COUNTIF('3121 ОС'!J6:J18,"-") | M16: Слаботочное/автоматика: зав. № и АоРПИ на оборудование отсутствуют; есть только кабельные АоРПИ.
A17: 3121 СКУД | B17: 3121 | C17: СКУД | D17: 03-91-1201-44-СКУД.СО-001 / 5 (.docx) | E17: =COUNTA('3121 СКУД'!B6:B15) | F17: =SUM('3121 СКУД'!E6:E15) | G17: =SUM('3121 СКУД'!G6:G15) | H17: =COUNTIF('3121 СКУД'!L6:L15,"Нет*") | I17: =COUNTIF('3121 СКУД'!L6:L15,"ОК*") | J17: =COUNTIF('3121 СКУД'!L6:L15,"*не подписан") | K17: =COUNTIF('3121 СКУД'!L6:L15,"Зав. № есть, АоРПИ нет") | L17: =COUNTIF('3121 СКУД'!J6:J15,"-") | M17: Слаботочное/автоматика: зав. № и АоРПИ на оборудование отсутствуют; есть только кабельные АоРПИ.
A18: 3121 ПС | B18: 3121 | C18: ПС | D18: 03-91-1201-44-ПС.СО-001 / 4B (.docx) | E18: =COUNTA('3121 ПС'!B6:B20) | F18: =SUM('3121 ПС'!E6:E20) | G18: =SUM('3121 ПС'!G6:G20) | H18: =COUNTIF('3121 ПС'!L6:L20,"Нет*") | I18: =COUNTIF('3121 ПС'!L6:L20,"ОК*") | J18: =COUNTIF('3121 ПС'!L6:L20,"*не подписан") | K18: =COUNTIF('3121 ПС'!L6:L20,"Зав. № есть, АоРПИ нет") | L18: =COUNTIF('3121 ПС'!J6:J20,"-") | M18: Слаботочное/автоматика: зав. № и АоРПИ на оборудование отсутствуют; есть только кабельные АоРПИ.
A19: 3121 АОВ | B19: 3121 | C19: АОВ | D19: 03-50-1201-44-АОВ.СО-001 / 4A (.xlsx) | E19: =COUNTA('3121 АОВ'!B6:B12) | F19: =SUM('3121 АОВ'!E6:E12) | G19: =SUM('3121 АОВ'!G6:G12) | H19: =COUNTIF('3121 АОВ'!L6:L12,"Нет*") | I19: =COUNTIF('3121 АОВ'!L6:L12,"ОК*") | J19: =COUNTIF('3121 АОВ'!L6:L12,"*не подписан") | K19: =COUNTIF('3121 АОВ'!L6:L12,"Зав. № есть, АоРПИ нет") | L19: =COUNTIF('3121 АОВ'!J6:J12,"-") | M19: Слаботочное/автоматика: зав. № и АоРПИ на оборудование отсутствуют; есть только кабельные АоРПИ.
A20: 3121 АОВ1 | B20: 3121 | C20: АОВ1 | D20: 03-50-1201-44-АОВ1.СО-001 / 4B (.doc) | E20: =COUNTA('3121 АОВ1'!B6:B13) | F20: =SUM('3121 АОВ1'!E6:E13) | G20: =SUM('3121 АОВ1'!G6:G13) | H20: =COUNTIF('3121 АОВ1'!L6:L13,"Нет*") | I20: =COUNTIF('3121 АОВ1'!L6:L13,"ОК*") | J20: =COUNTIF('3121 АОВ1'!L6:L13,"*не подписан") | K20: =COUNTIF('3121 АОВ1'!L6:L13,"Зав. № есть, АоРПИ нет") | L20: =COUNTIF('3121 АОВ1'!J6:J13,"-") | M20: Слаботочное/автоматика: зав. № и АоРПИ на оборудование отсутствуют; есть только кабельные АоРПИ.
A21: 3123 СС | B21: 3123 | C21: СС | D21: 03-91-1203-44-СС.СО-001 / 4B (.docx); в папке 5 — pdf | E21: =COUNTA('3123 СС'!B6:B9) | F21: =SUM('3123 СС'!E6:E9) | G21: =SUM('3123 СС'!G6:G9) | H21: =COUNTIF('3123 СС'!L6:L9,"Нет*") | I21: =COUNTIF('3123 СС'!L6:L9,"ОК*") | J21: =COUNTIF('3123 СС'!L6:L9,"*не подписан") | K21: =COUNTIF('3123 СС'!L6:L9,"Зав. № есть, АоРПИ нет") | L21: =COUNTIF('3123 СС'!J6:J9,"-") | M21: Слаботочное/автоматика: зав. № и АоРПИ на оборудование отсутствуют; есть только кабельные АоРПИ.
A22: 3123 ОС | B22: 3123 | C22: ОС | D22: 03-91-1203-44-ОС.СО-001 / 5 (.docx) | E22: =COUNTA('3123 ОС'!B6:B9) | F22: =SUM('3123 ОС'!E6:E9) | G22: =SUM('3123 ОС'!G6:G9) | H22: =COUNTIF('3123 ОС'!L6:L9,"Нет*") | I22: =COUNTIF('3123 ОС'!L6:L9,"ОК*") | J22: =COUNTIF('3123 ОС'!L6:L9,"*не подписан") | K22: =COUNTIF('3123 ОС'!L6:L9,"Зав. № есть, АоРПИ нет") | L22: =COUNTIF('3123 ОС'!J6:J9,"-") | M22: Слаботочное/автоматика: зав. № и АоРПИ на оборудование отсутствуют; есть только кабельные АоРПИ.
A23: 3123 СКУД | B23: 3123 | C23: СКУД | D23: 03-91-1203-44-СКУД.СО-001 / 5 (.docx) | E23: =COUNTA('3123 СКУД'!B6:B11) | F23: =SUM('3123 СКУД'!E6:E11) | G23: =SUM('3123 СКУД'!G6:G11) | H23: =COUNTIF('3123 СКУД'!L6:L11,"Нет*") | I23: =COUNTIF('3123 СКУД'!L6:L11,"ОК*") | J23: =COUNTIF('3123 СКУД'!L6:L11,"*не подписан") | K23: =COUNTIF('3123 СКУД'!L6:L11,"Зав. № есть, АоРПИ нет") | L23: =COUNTIF('3123 СКУД'!J6:J11,"-") | M23: Слаботочное/автоматика: зав. № и АоРПИ на оборудование отсутствуют; есть только кабельные АоРПИ.
A24: 3123 ПС | B24: 3123 | C24: ПС | D24: 03-91-1203-44-ПС.СО-001 / 4A (.docx) | E24: =COUNTA('3123 ПС'!B6:B13) | F24: =SUM('3123 ПС'!E6:E13) | G24: =SUM('3123 ПС'!G6:G13) | H24: =COUNTIF('3123 ПС'!L6:L13,"Нет*") | I24: =COUNTIF('3123 ПС'!L6:L13,"ОК*") | J24: =COUNTIF('3123 ПС'!L6:L13,"*не подписан") | K24: =COUNTIF('3123 ПС'!L6:L13,"Зав. № есть, АоРПИ нет") | L24: =COUNTIF('3123 ПС'!J6:J13,"-") | M24: Слаботочное/автоматика: зав. № и АоРПИ на оборудование отсутствуют; есть только кабельные АоРПИ.
A25: 3123 АОВ | B25: 3123 | C25: АОВ | D25: 03-50-1203-44-АОВ.СО-001 / 4A (.docx) | E25: =COUNTA('3123 АОВ'!B6:B8) | F25: =SUM('3123 АОВ'!E6:E8) | G25: =SUM('3123 АОВ'!G6:G8) | H25: =COUNTIF('3123 АОВ'!L6:L8,"Нет*") | I25: =COUNTIF('3123 АОВ'!L6:L8,"ОК*") | J25: =COUNTIF('3123 АОВ'!L6:L8,"*не подписан") | K25: =COUNTIF('3123 АОВ'!L6:L8,"Зав. № есть, АоРПИ нет") | L25: =COUNTIF('3123 АОВ'!J6:J8,"-") | M25: Слаботочное/автоматика: зав. № и АоРПИ на оборудование отсутствуют; есть только кабельные АоРПИ.
A26: 3123 АОВ1 | B26: 3123 | C26: АОВ1 | D26: 03-50-1203-44-АОВ1.СО-001 / 4B (.doc) | E26: =COUNTA('3123 АОВ1'!B6:B9) | F26: =SUM('3123 АОВ1'!E6:E9) | G26: =SUM('3123 АОВ1'!G6:G9) | H26: =COUNTIF('3123 АОВ1'!L6:L9,"Нет*") | I26: =COUNTIF('3123 АОВ1'!L6:L9,"ОК*") | J26: =COUNTIF('3123 АОВ1'!L6:L9,"*не подписан") | K26: =COUNTIF('3123 АОВ1'!L6:L9,"Зав. № есть, АоРПИ нет") | L26: =COUNTIF('3123 АОВ1'!J6:J9,"-") | M26: Слаботочное/автоматика: зав. № и АоРПИ на оборудование отсутствуют; есть только кабельные АоРПИ.
A27: 3128 ОС | B27: 3128 | C27: ОС | D27: 03-91-1200-44-ОС.СО-001 / 5 (.docx) | E27: =COUNTA('3128 ОС'!B6:B14) | F27: =SUM('3128 ОС'!E6:E14) | G27: =SUM('3128 ОС'!G6:G14) | H27: =COUNTIF('3128 ОС'!L6:L14,"Нет*") | I27: =COUNTIF('3128 ОС'!L6:L14,"ОК*") | J27: =COUNTIF('3128 ОС'!L6:L14,"*не подписан") | K27: =COUNTIF('3128 ОС'!L6:L14,"Зав. № есть, АоРПИ нет") | L27: =COUNTIF('3128 ОС'!J6:J14,"-") | M27: Слаботочное/автоматика: зав. № и АоРПИ на оборудование отсутствуют; есть только кабельные АоРПИ.
A28: 3128 СОО | B28: 3128 | C28: СОО | D28: 03-91-1200-44-СОО.СО-001 / 5 (.docx) | E28: =COUNTA('3128 СОО'!B6:B9) | F28: =SUM('3128 СОО'!E6:E9) | G28: =SUM('3128 СОО'!G6:G9) | H28: =COUNTIF('3128 СОО'!L6:L9,"Нет*") | I28: =COUNTIF('3128 СОО'!L6:L9,"ОК*") | J28: =COUNTIF('3128 СОО'!L6:L9,"*не подписан") | K28: =COUNTIF('3128 СОО'!L6:L9,"Зав. № есть, АоРПИ нет") | L28: =COUNTIF('3128 СОО'!J6:J9,"-") | M28: Слаботочное/автоматика: зав. № и АоРПИ на оборудование отсутствуют; есть только кабельные АоРПИ.
A29: 3128 СОТ | B29: 3128 | C29: СОТ | D29: 03-91-1200-44-СОТ.СО-001 / 5 (.xlsx) | E29: =COUNTA('3128 СОТ'!B6:B8) | F29: =SUM('3128 СОТ'!E6:E8) | G29: =SUM('3128 СОТ'!G6:G8) | H29: =COUNTIF('3128 СОТ'!L6:L8,"Нет*") | I29: =COUNTIF('3128 СОТ'!L6:L8,"ОК*") | J29: =COUNTIF('3128 СОТ'!L6:L8,"*не подписан") | K29: =COUNTIF('3128 СОТ'!L6:L8,"Зав. № есть, АоРПИ нет") | L29: =COUNTIF('3128 СОТ'!J6:J8,"-") | M29: Слаботочное/автоматика: зав. № и АоРПИ на оборудование отсутствуют; есть только кабельные АоРПИ.
C30: ИТОГО | E30: =SUM(E6:E29) | F30: =SUM(F6:F29) | G30: =SUM(G6:G29) | H30: =SUM(H6:H29) | I30: =SUM(I6:I29) | J30: =SUM(J6:J29) | K30: =SUM(K6:K29) | L30: =SUM(L6:L29)
A32: Как читать: вкладка раздела → столбец «Заводской №» (пусто = номер не найден ни в АоРПИ, ни в RFI), «АоРПИ» (- = акта в папке ВК нет), «Итог» — формула по этим столбцам.
A33: Вкладка «Нет зав. №» — сводный перечень того, по чему номеров не хватает (силовое оборудование 3120 выделено жёлтым).
A34: Столбцы O–R во вкладках 3120 — данные «Сводной по подстанции 17.08.2026» (RFI, АоРПИ, замечания) и результат сверки; недостающие RFI/АоРПИ и позиции (АРМ, КИП-С, резисторы, ЭНИП, БАП и др.) перенесены в свод. Статусы АоРПИ обновлены по папке ВК на 28.09.2026.
A35: Вкладка «АоРПИ» — все найденные акты по титулам 312х (кроме КЖ/КМ/ЭГ-материалов) со статусом и ссылками; «RFI» — разбор RFI 1440, 1472-1, 1576/1576-1, 1614/1614-1, 1709/1709(1), 1828 и др.

Sheet Нет зав. №
A1: Оборудование, на которое заводские номера не найдены (что нужно запросить)
A2: Сформировано из вкладок разделов: строки с пустым столбцом «Заводской №». Приоритет — силовое оборудование 3120 (ЭС1–ЭС5, АСУЭ, АИИСКУЭ).
A4: Вкладка | B4: Поз. / тег | C4: Наименование | D4: Тип, марка | E4: Кол-во | F4: RFI | G4: АоРПИ | H4: Примечание / где искать
A5: 3120 ЭС1 | B5: — | C5: Шкаф местного управления 1200х900х2000, IP55 | D5: ШМУ (Sieyuan) | E5: 2 | F5: 1440 | G5: - | H5: В RFI 1440 только чертёжный № SGF24012NS6010; зав. № не найден
A6: 3120 ЭС1 | B6: — | C6: Шкаф местного управления 980х900х2000, IP55 | D6: ШМУ (Sieyuan) | E6: 2 | F6: 1440 | G6: - | H6: В RFI 1440 чертёжные № SGF24012NS6020/6030; зав. № не найден
A7: 3120 ЭС1 | B7: — | C7: Шкаф онлайн-мониторинга 980х900х2000, IP54 | D7: Sieyuan | E7: 1 | F7: 1440 | G7: - | H7: В RFI 1440 «Система мониторинга» NS1313–1315 без зав. №
A8: 3120 ЭС1 | B8: — | C8: Токопровод 10 кВ закрытый 2000 А, 50 кА, с ОПН 10 кВ | D8: Jiangsu Shilin | E8: 4 | F8: 1332 | G8: - | H8: Возможно поставлен по RFI 1332 (GM-12/2000) — привязку к 3120 сверить
A9: 3120 ЭС1 | B9: — | C9: Токопровод 10 кВ закрытый 2000 А, 50 кА | D9: Jiangsu Shilin | E9: 2 | F9: 1332, 1613 | G9: - | H9: Возможно RFI 1332
A10: 3120 ЭС1 | B10: — | C10: Токопровод 10 кВ закрытый 100 А, 50 кА, с ОПН 10 кВ | D10: Jiangsu Shilin | E10: 2 | F10: 1332, 1613 | G10: -
A11: 3120 ЭС1 | B11: — | C11: Шкаф управления системой охлаждения трансформатора, IP54 | D11: ШУ-Д-2-380-16-4/2,5 | E11: 2 | F11: - | G11: - | H11: Вероятно в комплекте ТРДН — проверить паспорт E19006-PO-061-TP-0001
A12: 3120 ЭС3 | B12: 1.4 | C12: Стеллаж аккумуляторный двухъярусный | D12: ACM1-2 (ВОЛЬТАГ) | E12: 4 | F12: 1403 | G12: 816-3120-ЭС3-ВК-ЧНД
A13: 3120 ЭС3 | B13: 1.5 АБ1, АБ2 | C13: АКБ свинцово-кислотная 490 Ач, 104 эл. по 2 В | D13: OPzS 490 (ВОЛЬТАГ) | E13: 2 | F13: 1403 | G13: 816-3120-ЭС3-ВК-ЧНД | H13: Зав. № батарей не найдены
A14: 3120 ЭС3 | B14: 1.6 (03L1201) | C14: Кран мостовой однобалочный подвесной двухпролётный 10 т | D14: FHU10-15-9 A3 | E14: 1 | F14: 1292-1, 1292 | G14: 526-3121-КЭ-ЧНД | H14: В RFI/АоРПИ только индекс крана и тег 03L1201, зав. № нет
A15: 3120 ЭС3 | B15: 1.7 | C15: Шкаф управления краном 400 В, 600х900х220 | D15: FEC22058-06 | E15: 1 | F15: 1292-1, 1292 | G15: 526-3121-КЭ-ЧНД
A16: 3120 ЭС3 | B16: 1.8 DCW1.1N, DCW1.2N | C16: Ящик с рубильником и штепсельным разъёмом, IP54 | D16: ЯВЗШ-31-100 УХЛ1 | E16: 2 | F16: 1541 | G16: -
A17: 3120 ЭС3 | B17: 1.9 DCW2.1N…DCW3.2N | C17: Ящик с рубильником и штепсельным разъёмом, IP31 | D17: ЯВЗШ-31-100 УХЛ4 | E17: 6 | F17: 1541 | G17: -
A18: 3120 ЭС3 | B18: 1.10 DC2.1-2.2N | C18: Вторичная силовая сборка DC2.1-2.2N | E18: 1 | F18: 1671 | G18: -
A19: 3120 ЭС3 | B19: 1.11 DC2.3N | C19: Вторичная силовая сборка DC2.3N | E19: 1 | F19: 1671 | G19: -
A20: 3120 ЭС3 | B20: 1.12 DC2.5N | C20: Вторичная силовая сборка отопления DC2.5N | E20: 1 | F20: 1671 | G20: -
A21: 3120 ЭС3 | B21: 1.13 DC2.6N | C21: Вторичная силовая сборка отопления DC2.6N | E21: 1 | F21: 1671 | G21: -
A22: 3120 ЭС3 | B22: 1.14 DC2.7N | C22: Вторичная силовая сборка кондиционирования DC2.7N | E22: 1 | F22: 1671 | G22: -
A23: 3120 ЭС3 | B23: 1.15 DC2.8N | C23: Вторичная силовая сборка вентиляции DC2.8N | E23: 1 | F23: 1671 | G23: -
A24: 3120 ЭС3 | B24: 1.16 DC2.9N | C24: Вторичная силовая сборка вентиляции DC2.9N | E24: 1 | F24: 1671 | G24: -
A25: 3120 ЭС3 | B25: 1.17 DC2.10N | C25: Вторичная силовая сборка вентиляции DC2.10N | E25: 1 | F25: 1671 | G25: -
A26: 3120 ЭС3 | B26: 1.18 DC2.11N | C26: Вторичная силовая сборка вентиляции DC2.11N | E26: 1 | F26: 1671 | G26: -
A27: 3120 ЭС3 | B27: 1.19 DC2.12N | C27: Вторичная силовая сборка вентиляции DC2.12N | E27: 1 | F27: 1671 | G27: -
A28: 3120 ЭС3 | B28: 1.20 DC2.13N | C28: Вторичная силовая сборка вентиляции DC2.13N | E28: 1 | F28: 1671 | G28: -
A29: 3120 ЭС3 | B29: 1.21 DC3.1N | C29: Вторичная силовая сборка DC3.1N (устан. в ЗРУ-10 кВ тит. 3123) | E29: 1 | F29: 1671 | G29: -
... A31: 3120 ЭС3 | B31: 1.23 DCM3.1N | C31: Панель противопожарных устройств (ППУ), в ЗРУ-10 кВ тит. 3123 | E31: 1 | F31: 1671 | G31: -
A32: 3120 ЭС4 | B32: — | C32: Комплект ПО и оборудования для обмена с терминалами РЗА | D32: WINBRES, TRANSET, BRESUSB | E32: 2 | F32: - | G32: -
A33: 3120 ЭС4 | B33: — | C33: Ноутбук для обслуживания устройств РЗА | E33: 1 | F33: - | G33: -
A34: 3120 ЭС4 | B34: — | C34: Инструмент для монтажа и наладки ПТС РЗА | D34: Бреслер | E34: 1 | F34: - | G34: -
A35: 3120 ЭС5 | B35: ШЗВ | C35: Шкаф промежуточных зажимов, 30 зажимов | D35: ШЗВ-30 | E35: 1 | F35: 1671 | G35: - | H35: В папке АоРПИ 742-3120-ЭС5 лежит копия акта 961 (ЭС4) — акта на ЭС5 фактически нет
A36: 3120 ЭС5 | B36: ШПС | C36: Шкаф повторителей сигнала | D36: ШПС | E36: 1 | F36: 1671 | G36: -
A37: 3120 АСУЭ | B37: АРМ 4051 | C37: Монитор Delta Computers 27" | D37: М2701/2КР/LCD | E37: 6 | F37: 1556(1) | G37: -
A38: 3120 АСУЭ | B38: АРМ 4051 | C38: Принтер HP Color LaserJet CP5225dn | D38: CE712A | E38: 1 | F38: 1556(1) | G38: -
A39: 3120 АСУЭ | B39: АРМ 4051 | C39: МФУ HP LaserJet Pro 4103dw | D39: 2Z627A | E39: 1 | F39: 1556(1) | G39: -
A40: 3120 АСУЭ | B40: АРМ СМиУКЭ/РЗА/АСУЭ | C40: Ноутбук Acer Aspire 5 A515-57 | D40: A515-57-506D | E40: 3 | F40: 1556(1) | G40: -
A41: 3120 АСУЭ | B41: — | C41: Антенна ГЛОНАСС/GPS | D41: GPS-P.50MP | E41: 3 | F41: 1556(1) | G41: -
A42: 3120 АСУЭ | B42: — | C42: Метеостанция | D42: IMETEOLABS PWS-600R | E42: 1 | F42: 1556(2), 1556(1) | G42: - | H42: Поставлена в ЗИП RFI 1556(2), зав. № не указан
...

Sheet Пояснения
A1: Пояснения к своду
A3: ЦЕЛЬ
A4: Задача | B4: По РД главной подстанции (титулы 3120, 3121, 3123, 3128) выделить оборудование из спецификаций, найти заводские номера и АоРПИ; где номера нет — оставить пусто, где АоРПИ нет — «-».
A5: ИСТОЧНИКИ
A6: РД / СО | B6: SMB-46/PTO/6. Electric электрический/1.Последние чертежи/3120 и подпапка «Спецификация материалов» (doc/docx/xlsx последних ревизий). Из каждой СО взят раздел «Оборудование» (для слаботочки — приборы и устройства, без кабелей и материалов).
A7: АоРПИ | B7: Sharepoint/02-PTO/05 RFI & Incoming control/2.Incoming control/1.Closed (подписан) и 2.Open (не подписан); акты в формате разработки — SMB-46/PTO/Alfa-prom/Входной контроль (База Данных) (статус «Не подписан», если в 2.Open не загружены). Старая папка Alfa-prom/Incoming control удалена и не учитывается.
A8: RFI | B8: Sharepoint/02-PTO/05 RFI & Incoming control/1.RFI/CHENGDA (1541 RFI-форм просмотрено); заводские номера взяты из поля «Объект инспекции» и Приложений № 2.
A9: Паспорта | B9: Sharepoint/_Текст для поиска (распознанный текст PDF): зав. № трансформаторов 005214V/005215V взяты из текста АоРПИ 477/478.
A10: ОГРАНИЧЕНИЯ
A11: 1 | B11: СО перепроверены 28.09.2026: АСУЭ — по ревизии 4С (10.07.2026), АИИСКУЭ — по 4B (13.08.2026), ЭС4 — 4А (новее нет). Состав шкафов АСУЭ/АИИСКУЭ не изменился; в АИИСКУЭ изменены марки счётчиков (СТЭМ-300.263SU/153SU) и ноутбук АРМ инженера. ЗИП (раздел 5) в свод не включён.
A12: 2 | B12: Для светильников, извещателей и т.п. заводские номера в документах поставки не указываются — такие строки будут «без зав. №» по определению.
A13: 3 | B13: Номер ЩСН: в АоРПИ 806 и RFI 1560-2 — 297-25, в отклонённом RFI 1560-1 — 189-25. Номер ЩПТ: паспорта 25002 (№1) и 25003 (№2), в АоРПИ 816 — «ЩПТ №2 25002».
A14: ЦВЕТА | B14: Зелёный — зав. № есть и АоРПИ подписан; жёлтый — зав. № есть, но АоРПИ не подписан/нет или номера не все; красный — зав. № не найден.

Sheet 3120 ЭС1
A1: Титул 3120, раздел ЭС1 — оборудование (раздел «Оборудование» спецификации), заводские номера и АоРПИ
A2: СО: E19006-CXPP-3120-ЭС1.СО-001 (03-90-1200-44-ЭС.СО-001), ревизия 4А (Спецификация материалов/.doc)
A3: Зав. № и АоРПИ собраны из папок Nextcloud: 2.Incoming control (1.Closed — подписан, 2.Open — не подписан), 1.RFI/CHENGDA, _Текст для поиска. «-» в столбце АоРПИ — акта в папке ВК нет.
A5: Поз. / тег | B5: Наименование (по СО) | C5: Тип, марка | D5: Ед. | E5: Кол-во по СО | F5: Заводской № (пусто — не найден) | G5: Найдено зав. №, шт | H5: Источник зав. № | I5: RFI | J5: АоРПИ (- если нет) | K5: Статус АоРПИ | L5: Итог | M5: Примечание | N5: Паспорт (TP) | O5: RFI по сводной 17.08.2026 | P5: АоРПИ по сводной 17.08.2026 | Q5: Замечание из сводной 17.08.2026 | R5: Сверка со сводной 17.08.2026
A6: 0312GIS01 | B6: КРУЭ 220 кВ по типовой схеме 220-5АН, 4000 А, 50 кА | C6: ZF28-252 (Shanghai Sieyuan) | D6: компл. | E6: 1 | F6: SGF24012NSD01; SGF24012NSD02; SGF24012NSD03; SGF24012NSD04 | G6: 4 | H6: RFI 1440 (отклонён) | I6: 1440 | J6: - | K6: - | L6: =IF(F6="",IF(J6="-","Нет зав. №, нет АоРПИ","Нет зав. №"),IF(G6<E6,"Зав. № не все ("&G6&" из "&E6&")",IF(J6="-","Зав. № есть, АоРПИ нет",IF(K6="Подписан","ОК: зав. № + АоРПИ подписан","Зав. № есть, АоРПИ не подписан")))) | M6: 4 зав. № — по транспортным блокам КРУЭ. Документы Чэнда по RFI 1440 от 22.09.2026 (TRM 18712) — только паспорта ОПН (TP-0007), паспортов КРУЭ с зав. № нет. RFI 1440 отклонён, повторного RFI нет; АоРПИ нет | O6: CHENGDA-MU-IC-1440 | P6: нет, акт рабочий лист | Q6: Документы отклонены заказчиком. Исправленных документов не получали. | R6: Совпадает
A7: — | B7: Шкаф местного управления 1200х900х2000, IP55 | C7: ШМУ (Sieyuan) | D7: компл. | E7: 2 | G7: 0 | I7: 1440 | J7: - | K7: - | L7: =IF(F7="",IF(J7="-","Нет зав. №, нет АоРПИ","Нет зав. №"),IF(G7<E7,"Зав. № не все ("&G7&" из "&E7&")",IF(J7="-","Зав. № есть, АоРПИ нет",IF(K7="Подписан","ОК: зав. № + АоРПИ подписан","Зав. № есть, АоРПИ не подписан")))) | M7: В RFI 1440 только чертёжный № SGF24012NS6010; зав. № не найден | O7: CHENGDA-MU-IC-1440 | P7: нет, акт рабочий лист | Q7: Документов нет, в первом комплекте документы на данные позиции отсутствовали. | R7: кол-во: в СО 2, в сводной 3
A8: — | B8: Шкаф местного управления 980х900х2000, IP55 | C8: ШМУ (Sieyuan) | D8: компл. | E8: 2 | G8: 0 | I8: 1440 | J8: - | K8: - | L8: =IF(F8="",IF(J8="-","Нет зав. №, нет АоРПИ","Нет зав. №"),IF(G8<E8,"Зав. № не все ("&G8&" из "&E8&")",IF(J8="-","Зав. № есть, АоРПИ нет",IF(K8="Подписан","ОК: зав. № + АоРПИ подписан","Зав. № есть, АоРПИ не подписан")))) | M8: В RFI 1440 чертёжные № SGF24012NS6020/6030; зав. № не найден | O8: CHENGDA-MU-IC-1440 | P8: нет, акт рабочий лист | Q8: Документов нет, в первом комплекте документы на данные позиции отсутствовали. | R8: Совпадает
A9: — | B9: Шкаф онлайн-мониторинга 980х900х2000, IP54 | C9: Sieyuan | D9: компл. | E9: 1 | G9: 0 | I9: 1440 | J9: - | K9: - | L9: =IF(F9="",IF(J9="-","Нет зав. №, нет АоРПИ","Нет зав. №"),IF(G9<E9,"Зав. № не все ("&G9&" из "&E9&")",IF(J9="-","Зав. № есть, АоРПИ нет",IF(K9="Подписан","ОК: зав. № + АоРПИ подписан","Зав. № есть, АоРПИ не подписан")))) | M9: В RFI 1440 «Система мониторинга» NS1313–1315 без зав. № | O9: CHENGDA-MU-IC-1440 | P9: нет, акт рабочий лист | Q9: Документов нет, в первом комплекте документы на данные позиции отсутствовали. | R9: Совпадает
A10: 0312TRA01, 0312TRA02 | B10: Трансформатор силовой масляный с расщеплённой обмоткой 63 МВА, РПН | C10: ТРДН-63000/220-УХЛ1 (ERSO) | D10: компл. | E10: 2 | F10: 005214V (0312TRE01); 005215V (0312TRE02) | G10: 2 | H10: АоРПИ 477, 478 | I10: 1293-2, 1293 | J10: 477-3120-ТР-ЧНД, 478-3120-ТР-ЧНД | K10: Подписан | L10: =IF(F10="",IF(J10="-","Нет зав. №, нет АоРПИ","Нет зав. №"),IF(G10<E10,"Зав. № не все ("&G10&" из "&E10&")",IF(J10="-","Зав. № есть, АоРПИ нет",IF(K10="Подписан","ОК: зав. № + АоРПИ подписан","Зав. № есть, АоРПИ не подписан")))) | M10: В СО теги 0312TRA01/02, в RFI и АоРПИ — 0312TRE01/02 | O10: CHENGDA-MU-IC-1293 | P10: 477-3120-TP-ЧНД 478-3120-TP-ЧНД | R10: RFI 1293 добавлен из сводной
A11: — | B11: Ограничитель перенапряжений 220 кВ | C11: ОПНп-220/680/163-10-IV УХЛ1 (Полимер-Аппарат) | D11: шт | E11: 12 | F11: 253392; 253393; 253394; 253395; 253396; 253397; 253398; 253399; 253400; 253401; 253402; 253403 | G11: 12 | H11: RFI 1440(1); паспорта TP-0007 1B | I11: 1440(1), 1440 | J11: 1248-3120-ЭС1-ВК-ЧНД | K11: Не подписан | L11: =IF(F11="",IF(J11="-","Нет зав. №, нет АоРПИ","Нет зав. №"),IF(G11<E11,"Зав. № не все ("&G11&" из "&E11&")",IF(J11="-","Зав. № есть, АоРПИ нет",IF(K11="Подписан","ОК: зав. № + АоРПИ подписан","Зав. № есть, АоРПИ не подписан")))) | M11: Все 12 зав. № подтверждены паспортами E19006-PO-062-TP-0007 1B (ОТК 14.11.2025, Полимер-Аппарат). В АоРПИ 1248 зав. № не указаны — дописать | N11: E19006-PO-062-TP-0007 1B — 12 паспортов, зав. № 253392–253403 (ОТК 14.11.2025) | O11: CHENGDA-MU-IC-1440 | P11: 1248-3120-ЭС1-ВК-ЧНД | Q11: Сделали | R11: RFI 1440 добавлен из сводной
A12: — | B12: Токопровод 10 кВ закрытый 2000 А, 50 кА, с ОПН 10 кВ | C12: Jiangsu Shilin | D12: компл. | E12: 4 | G12: 0 | I12: 1332 | J12: - | K12: - | L12: =IF(F12="",IF(J12="-","Нет зав. №, нет АоРПИ","Нет зав. №"),IF(G12<E12,"Зав. № не все ("&G12&" из "&E12&")",IF(J12="-","Зав. № есть, АоРПИ нет",IF(K12="Подписан","ОК: зав. № + АоРПИ подписан","Зав. № есть, АоРПИ не подписан")))) | M12: Возможно поставлен по RFI 1332 (GM-12/2000) — привязку к 3120 сверить | O12: CHENGDA-MU-IC-1332 | P12: нет, акт рабочий лист | Q12: RFI на проверке в НГС с 22.04.2026 | R12: Совпадает
A13: — | B13: Токопровод 10 кВ закрытый 2000 А, 50 кА | C13: Jiangsu Shilin | D13: компл. | E13: 2 | G13: 0 | I13: 1332, 1613 | J13: - | K13: - | L13: =IF(F13="",IF(J13="-","Нет зав. №, нет АоРПИ","Нет зав. №"),IF(G13<E13,"Зав. № не все ("&G13&" из "&E13&")",IF(J13="-","Зав. № есть, АоРПИ нет",IF(K13="Подписан","ОК: зав. № + АоРПИ подписан","Зав. № есть, АоРПИ не подписан")))) | M13: Возможно RFI 1332 | O13: CHENGDA-MU-IC-1332 / CHENGDA-MU-IC-1613 | P13: нет, акт рабочий лист | Q13: Не понятно какой участок? Если от ЗРУ до Реакторов дугогасящих, то нет документов, если на подстанцию ГТГ 3103 то тоже нет документов. | R13: RFI 1613 добавлен из сводной
A14: — | B14: Токопровод 10 кВ закрытый 100 А, 50 кА, с ОПН 10 кВ | C14: Jiangsu Shilin | D14: компл. | E14: 2 | G14: 0 | I14: 1332, 1613 | J14: - | K14: - | L14: =IF(F14="",IF(J14="-","Нет зав. №, нет АоРПИ","Нет зав. №"),IF(G14<E14,"Зав. № не все ("&G14&" из "&E14&")",IF(J14="-","Зав. № есть, АоРПИ нет",IF(K14="Подписан","ОК: зав. № + АоРПИ подписан","Зав. № есть, АоРПИ не подписан")))) | O14: CHENGDA-MU-IC-1332 / CHENGDA-MU-IC-1613 | P14: нет, акт рабочий лист | Q14: Не понятно какой участок? Если от ЗРУ до Реакторов дугогасящих, то нет документов, если на подстанцию ГТГ 3103 то тоже нет документов. | R14: RFI 1332 добавлен из сводной; RFI 1613 добавлен из сводной
A15: — | B15: Шкаф управления системой охлаждения трансформатора, IP54 | C15: ШУ-Д-2-380-16-4/2,5 | D15: компл. | E15: 2 | G15: 0 | I15: - | J15: - | K15: - | L15: =IF(F15="",IF(J15="-","Нет зав. №, нет АоРПИ","Нет зав. №"),IF(G15<E15,"Зав. № не все ("&G15&" из "&E15&")",IF(J15="-","Зав. № есть, АоРПИ нет",IF(K15="Подписан","ОК: зав. № + АоРПИ подписан","Зав. № есть, АоРПИ не подписан")))) | M15: Вероятно в комплекте ТРДН — проверить паспорт E19006-PO-061-TP-0001 | O15: нет | P15: нет | R15: Совпадает
D16: Итого | E16: =SUM(E6:E15) | G16: =SUM(G6:G15)

Sheet 3120 ЭС2
A1: Титул 3120, раздел ЭС2 — оборудование (раздел «Оборудование» спецификации), заводские номера и АоРПИ
A2: СО: E19006-CXPP-3120-ЭС2.СО-001, ревизия 4А (.xlsx)
A3: Зав. № и АоРПИ собраны из папок Nextcloud: 2.Incoming control (1.Closed — подписан, 2.Open — не подписан), 1.RFI/CHENGDA, _Текст для поиска. «-» в столбце АоРПИ — акта в папке ВК нет.
A5: Поз. / тег | B5: Наименование (по СО) | C5: Тип, марка | D5: Ед. | E5: Кол-во по СО | F5: Заводской № (пусто — не найден) | G5: Найдено зав. №, шт | H5: Источник зав. № | I5: RFI | J5: АоРПИ (- если нет) | K5: Статус АоРПИ | L5: Итог | M5: Примечание | N5: Паспорт (TP) | O5: RFI по сводной 17.08.2026 | P5: АоРПИ по сводной 17.08.2026 | Q5: Замечание из сводной 17.08.2026 | R5: Сверка со сводной 17.08.2026
A6: 1.1 яч. 101 Резерв | B6: Ячейка КРУ-10 кВ (в составе КРУ 22 ячейки, VS1-EZ-12, Бреслер-0107) | C6: КРУ-ЭЗ-10-40 (Энергозащита) | D6: шт | E6: 1 | F6: 15007069 | G6: 1 | H6: АоРПИ 720 | I6: 1448 | J6: 720-3120-ЭС2-ВК-ЧНД | K6: Подписан | L6: =IF(F6="",IF(J6="-","Нет зав. №, нет АоРПИ","Нет зав. №"),IF(G6<E6,"Зав. № не все ("&G6&" из "&E6&")",IF(J6="-","Зав. № есть, АоРПИ нет",IF(K6="Подписан","ОК: зав. № + АоРПИ подписан","Зав. № есть, АоРПИ не подписан")))) | O6: CHENGDA-MU-IC-1448 | P6: 720-3120-ЭС2-ВК-ЧНД | R6: Совпадает
A7: 1.1 яч. 102 ОЛ резерв | B7: Ячейка КРУ-10 кВ (в составе КРУ 22 ячейки, VS1-EZ-12, Бреслер-0107) | C7: КРУ-ЭЗ-10-40 (Энергозащита) | D7: шт | E7: 1 | F7: 15007081 | G7: 1 | H7: АоРПИ 720 | I7: 1448 | J7: 720-3120-ЭС2-ВК-ЧНД | K7: Подписан | L7: =IF(F7="",IF(J7="-","Нет зав. №, нет АоРПИ","Нет зав. №"),IF(G7<E7,"Зав. № не все ("&G7&" из "&E7&")",IF(J7="-","Зав. № есть, АоРПИ нет",IF(K7="Подписан","ОК: зав. № + АоРПИ подписан","Зав. № есть, АоРПИ не подписан")))) | O7: CHENGDA-MU-IC-1448 | P7: 720-3120-ЭС2-ВК-ЧНД | R7: Совпадает
A8: 1.1 яч. 103 ОЛ ТСН1 | B8: Ячейка КРУ-10 кВ (в составе КРУ 22 ячейки, VS1-EZ-12, Бреслер-0107) | C8: КРУ-ЭЗ-10-40 (Энергозащита) | D8: шт | E8: 1 | F8: 15007083 | G8: 1 | H8: АоРПИ 720 | I8: 1448 | J8: 720-3120-ЭС2-ВК-ЧНД | K8: Подписан | L8: =IF(F8="",IF(J8="-","Нет зав. №, нет АоРПИ","Нет зав. №"),IF(G8<E8,"Зав. № не все ("&G8&" из "&E8&")",IF(J8="-","Зав. № есть, АоРПИ нет",IF(K8="Подписан","ОК: зав. № + АоРПИ подписан","Зав. № есть, АоРПИ не подписан")))) | O8: CHENGDA-MU-IC-1448 | P8: 720-3120-ЭС2-ВК-ЧНД | R8: Совпадает
A9: 1.1 яч. 104 ТН1 | B9: Ячейка КРУ-10 кВ (в составе КРУ 22 ячейки, VS1-EZ-12, Бреслер-0107) | C9: КРУ-ЭЗ-10-40 (Энергозащита) | D9: шт | E9: 1 | F9: 15007075 | G9: 1 | H9: АоРПИ 720 | I9: 1448 | J9: 720-3120-ЭС2-ВК-ЧНД | K9: Подписан | L9: =IF(F9="",IF(J9="-","Нет зав. №, нет АоРПИ","Нет зав. №"),IF(G9<E9,"Зав. № не все ("&G9&" из "&E9&")",IF(J9="-","Зав. № есть, АоРПИ нет",IF(K9="Подписан","ОК: зав. № + АоРПИ подписан","Зав. № есть, АоРПИ не подписан")))) | O9: CHENGDA-MU-IC-1448 | P9: 720-3120-ЭС2-ВК-ЧНД | R9: Совпадает
A10: 1.1 яч. 105 Ввод 1 | B10: Ячейка КРУ-10 кВ (в составе КРУ 22 ячейки, VS1-EZ-12, Бреслер-0107) | C10: КРУ-ЭЗ-10-40 (Энергозащита) | D10: шт | E10: 1 | F10: 15007063 | G10: 1 | H10: АоРПИ 720 | I10: 1448 | J10: 720-3120-ЭС2-ВК-ЧНД | K10: Подписан | L10: =IF(F10="",IF(J10="-","Нет зав. №, нет АоРПИ","Нет зав. №"),IF(G10<E10,"Зав. № не все ("&G10&" из "&E10&")",IF(J10="-","Зав. № есть, АоРПИ нет",IF(K10="Подписан","ОК: зав. № + АоРПИ подписан","Зав. № есть, АоРПИ не подписан")))) | O10: CHENGDA-MU-IC-1448 | P10: 720-3120-ЭС2-ВК-ЧНД | R10: Совпадает
A11: 1.1 яч. 106 СВ1-3 | B11: Ячейка КРУ-10 кВ (в составе КРУ 22 ячейки, VS1-EZ-12, Бреслер-0107) | C11: КРУ-ЭЗ-10-40 (Энергозащита) | D11: шт | E11: 1 | F11: 15007071 | G11: 1 | H11: АоРПИ 720 | I11: 1448 | J11: 720-3120-ЭС2-ВК-ЧНД | K11: Подписан | L11: =IF(F11="",IF(J11="-","Нет зав. №, нет АоРПИ","Нет зав. №"),IF(G11<E11,"Зав. № не все ("&G11&" из "&E11&")",IF(J11="-","Зав. № есть, АоРПИ нет",IF(K11="Подписан","ОК: зав. № + АоРПИ подписан","Зав. № есть, АоРПИ не подписан")))) | O11: CHENGDA-MU-IC-1448 | P11: 720-3120-ЭС2-ВК-ЧНД | R11: Совпадает
A12: 1.1 яч. 201 СВ2-4 | B12: Ячейка КРУ-10 кВ (в составе КРУ 22 ячейки, VS1-EZ-12, Бреслер-0107) | C12: КРУ-ЭЗ-10-40 (Энергозащита) | D12: шт | E12: 1 | F12: 15007072 | G12: 1 | H12: АоРПИ 720 | I12: 1448 | J12: 720-3120-ЭС2-ВК-ЧНД | K12: Подписан | L12: =IF(F12="",IF(J12="-","Нет зав. №, нет АоРПИ","Нет зав. №"),IF(G12<E12,"Зав. № не все ("&G12&" из "&E12&")",IF(J12="-","Зав. № есть, АоРПИ нет",IF(K12="Подписан","ОК: зав. № + АоРПИ подписан","Зав. № есть, АоРПИ не подписан")))) | O12: CHENGDA-MU-IC-1448 | P12: 720-3120-ЭС2-ВК-ЧНД | R12: Совпадает
A13: 1.1 яч. 202 ТН2 | B13: Ячейка КРУ-10 кВ (в составе КРУ 22 ячейки, VS1-EZ-12, Бреслер-0107) | C13: КРУ-ЭЗ-10-40 (Энергозащита) | D13: шт | E13: 1 | F13: 15007076 | G13: 1 | H13: АоРПИ 720 | I13: 1448 | J13: 720-3120-ЭС2-ВК-ЧНД | K13: Подписан | L13: =IF(F13="",IF(J13="-","Нет зав. №, нет АоРПИ","Нет зав. №"),IF(G13<E13,"Зав. № не все ("&G13&" из "&E13&")",IF(J13="-","Зав. № есть, АоРПИ нет",IF(K13="Подписан","ОК: зав. № + АоРПИ подписан","Зав. № есть, АоРПИ не подписан")))) | O13: CHENGDA-MU-IC-1448 | P13: 720-3120-ЭС2-ВК-ЧНД | R13: Совпадает
A14: 1.1 яч. 203 Ввод 2 | B14: Ячейка КРУ-10 кВ (в составе КРУ 22 ячейки, VS1-EZ-12, Бреслер-0107) | C14: КРУ-ЭЗ-10-40 (Энергозащита) | D14: шт | E14: 1 | F14: 15007064 | G14: 1 | H14: АоРПИ 720 | I14: 1448 | J14: 720-3120-ЭС2-ВК-ЧНД | K14: Подписан | L14: =IF(F14="",IF(J14="-","Нет зав. №, нет АоРПИ","Нет зав. №"),IF(G14<E14,"Зав. № не все ("&G14&" из "&E14&")",IF(J14="-","Зав. № есть, АоРПИ нет",IF(K14="Подписан","ОК: зав. № + АоРПИ подписан","Зав. № есть, АоРПИ не подписан")))) | O14: CHENGDA-MU-IC-1448 | P14: 720-3120-ЭС2-ВК-ЧНД | R14: Совпадает
A15: 1.1 яч. 204 ОЛ ГТУ ф.1 | B15: Ячейка КРУ-10 кВ (в составе КРУ 22 ячейки, VS1-EZ-12, Бреслер-0107) | C15: КРУ-ЭЗ-10-40 (Энергозащита) | D15: шт | E15: 1 | F15: 15007067 | G15: 1 | H15: АоРПИ 720 | I15: 1448 | J15: 720-3120-ЭС2-ВК-ЧНД | K15: Подписан | L15: =IF(F15="",IF(J15="-","Нет зав. №, нет АоРПИ","Нет зав. №"),IF(G15<E15,"Зав. № не все ("&G15&" из "&E15&")",IF(J15="-","Зав. № есть, АоРПИ нет",IF(K15="Подписан","ОК: зав. № + АоРПИ подписан","Зав. № есть, АоРПИ не подписан")))) | O15: CHENGDA-MU-IC-1448 | P15: 720-3120-ЭС2-ВК-ЧНД | R15: Совпадает
A16: 1.1 яч. 205 ОЛ ДГР-1 | B16: Ячейка КРУ-10 кВ (в составе КРУ 22 ячейки, VS1-EZ-12, Бреслер-0107) | C16: КРУ-ЭЗ-10-40 (Энергозащита) | D16: шт | E16: 1 | F16: 15007079 | G16: 1 | H16: АоРПИ 720 | I16: 1448 | J16: 720-3120-ЭС2-ВК-ЧНД | K16: Подписан | L16: =IF(F16="",IF(J16="-","Нет зав. №, нет АоРПИ","Нет зав. №"),IF(G16<E16,"Зав. № не все ("&G16&" из "&E16&")",IF(J16="-","Зав. № есть, АоРПИ нет",IF(K16="Подписан","ОК: зав. № + АоРПИ подписан","Зав. № есть, АоРПИ не подписан")))) | O16: CHENGDA-MU-IC-1448 | P16: 720-3120-ЭС2-ВК-ЧНД | R16: Совпадает
A17: 1.1 яч. 301 СР1-3 | B17: Ячейка КРУ-10 кВ (в составе КРУ 22 ячейки, VS1-EZ-12, Бреслер-0107) | C17: КРУ-ЭЗ-10-40 (Энергозащита) | D17: шт | E17: 1 | F17: 15007073 | G17: 1 | H17: АоРПИ 720 | I17: 1448 | J17: 720-3120-ЭС2-ВК-ЧНД | K17: Подписан | L17: =IF(F17="",IF(J17="-","Нет зав. №, нет АоРПИ","Нет зав. №"),IF(G17<E17,"Зав. № не все ("&G17&" из "&E17&")",IF(J17="-","Зав. № есть, АоРПИ нет",IF(K17="Подписан","ОК: зав. № + АоРПИ подписан","Зав. № есть, АоРПИ не подписан")))) | O17: CHENGDA-MU-IC-1448 | P17: 720-3120-ЭС2-ВК-ЧНД | R17: Совпадает
... A27: 1.1 яч. 405 СР2-4 | B27: Ячейка КРУ-10 кВ (в составе КРУ 22 ячейки, VS1-EZ-12, Бреслер-0107) | C27: КРУ-ЭЗ-10-40 (Энергозащита) | D27: шт | E27: 1 | F27: 15007074 | G27: 1 | H27: АоРПИ 720 | I27: 1448 | J27: 720-3120-ЭС2-ВК-ЧНД | K27: Подписан | L27: =IF(F27="",IF(J27="-","Нет зав. №, нет АоРПИ","Нет зав. №"),IF(G27<E27,"Зав. № не все ("&G27&" из "&E27&")",IF(J27="-","Зав. № есть, АоРПИ нет",IF(K27="Подписан","ОК: зав. № + АоРПИ подписан","Зав. № есть, АоРПИ не подписан")))) | O27: CHENGDA-MU-IC-1448 | P27: 720-3120-ЭС2-ВК-ЧНД | R27: Совпадает
A28: 1.2 ШМ-ГТУ-1,2; ШМ-ДГР-2,4; ШМ-Т-1-1,2; ШМ-Т-2-3,4 | B28: Шинный мост вводной 10 кВ, 2000 А | C28: ВШМ-10-40 (Энергозащита) | D28: шт | E28: 8 | F28: 15007087 (ГТУ ф.1); 15007088 (ГТУ ф.2); 15007089 (Ввод 1); 15007091 (Ввод 2); 15007090 (Ввод 3); 15007092 (Ввод 4); 15007093 (яч.205); 15007094 (яч.401) | G28: 8 | H28: АоРПИ 720 | I28: 1448 | J28: 720-3120-ЭС2-ВК-ЧНД | K28: Подписан | L28: =IF(F28="",IF(J28="-","Нет зав. №, нет АоРПИ","Нет зав. №"),IF(G28<E28,"Зав. № не все ("&G28&" из "&E28&")",IF(J28="-","Зав. № есть, АоРПИ нет",IF(K28="Подписан","ОК: зав. № + АоРПИ подписан","Зав. № есть, АоРПИ не подписан")))) | M28: Мосты к яч. 205/401 по АоРПИ — ВШМ-10-40/1250 | O28: CHENGDA-MU-IC-1448 | P28: 720-3120-ЭС2-ВК-ЧНД | R28: Совпадает
A29: 1.3 ШМ-С-1, ШМ-С-2 | B29: Шинный мост секционный 10 кВ, 2000 А | C29: ВШМ-10-40/2000-23 УЗ | D29: шт | E29: 2 | F29: 15007095 (СВ 1-3); 15007096 (СВ 2-4) | G29: 2 | H29: АоРПИ 720 | I29: 1448 | J29: 720-3120-ЭС2-ВК-ЧНД | K29: Подписан | L29: =IF(F29="",IF(J29="-","Нет зав. №, нет АоРПИ","Нет зав. №"),IF(G29<E29,"Зав. № не все ("&G29&" из "&E29&")",IF(J29="-","Зав. № есть, АоРПИ нет",IF(K29="Подписан","ОК: зав. № + АоРПИ подписан","Зав. № есть, АоРПИ не подписан")))) | O29: CHENGDA-MU-IC-1448 | P29: 720-3120-ЭС2-ВК-ЧНД | R29: Совпадает
A30: 1.4 | B30: Дугогасящий реактор 500 кВА, 11/√3 кВ | C30: РДМР-500/10 У1 | D30: шт | E30: 2 | F30: 975; 976 | G30: 2 | H30: АоРПИ 651 / RFI 1380 | I30: 1380 | J30: 651-3120-ЭС2-ВК-ЧНД | K30: Подписан | L30: =IF(F30="",IF(J30="-","Нет зав. №, нет АоРПИ","Нет зав. №"),IF(G30<E30,"Зав. № не все ("&G30&" из "&E30&")",IF(J30="-","Зав. № есть, АоРПИ нет",IF(K30="Подписан","ОК: зав. № + АоРПИ подписан","Зав. № есть, АоРПИ не подписан")))) | O30: CHENGDA-MU-IC-1380 | P30: 651-3120-ЭС2-ВК-ЧНД | R30: Совпадает
A31: 1.5 | B31: Разъединитель однополюсный 35 кВ, 1000 А | C31: РГ-35II/1000-20УХЛ1 | D31: шт | E31: 2 | F31: 5; 6 | G31: 2 | H31: АоРПИ 651 / RFI 1380 | I31: 1380 | J31: 651-3120-ЭС2-ВК-ЧНД | K31: Подписан | L31: =IF(F31="",IF(J31="-","Нет зав. №, нет АоРПИ","Нет зав. №"),IF(G31<E31,"Зав. № не все ("&G31&" из "&E31&")",IF(J31="-","Зав. № есть, АоРПИ нет",IF(K31="Подписан","ОК: зав. № + АоРПИ подписан","Зав. № есть, АоРПИ не подписан")))) | M31: Включён в АоРПИ 651 (PO-155, RFI 1380) | O31: CHENGDA-MU-IC-1380 | P31: 651-3120-ЭС2-ВК-ЧНД | R31: Совпадает
A32: 1.6 | B32: Фильтр заземляющий 500 кВА, 11/√3 кВ (по TQ заменён на трансформатор ТМГ21-630/10-УХЛ1) | C32: ТМГ21-630/10-УХЛ1 | D32: шт | E32: 2 | F32: 2152742; 2152756 | G32: 2 | H32: АоРПИ 651 / RFI 1380 | I32: 1380 | J32: 651-3120-ЭС2-ВК-ЧНД | K32: Подписан | L32: =IF(F32="",IF(J32="-","Нет зав. №, нет АоРПИ","Нет зав. №"),IF(G32<E32,"Зав. № не все ("&G32&" из "&E32&")",IF(J32="-","Зав. № есть, АоРПИ нет",IF(K32="Подписан","ОК: зав. № + АоРПИ подписан","Зав. № есть, АоРПИ не подписан")))) | M32: По TQ фильтры заменены на трансформаторы ТМГ21-630/10-УХЛ1; в АоРПИ 651 — зав. № 2152742, 2152756 (PO-155, RFI 1380) | O32: CHENGDA-MU-IC-1380 | P32: 651-3120-ЭС2-ВК-ЧНД | R32: Совпадает
D33: Итого | E33: =SUM(E6:E32) | G33: =SUM(G6:G32)

Sheet 3120 ЭС3
A1: Титул 3120, раздел ЭС3 — оборудование (раздел «Оборудование» спецификации), заводские номера и АоРПИ
A2: СО: E19006-CXPP-3120-ЭС3.СО-001, ревизия 4В (папка «Последняя версия 2026-4-4», .xlsx)
A3: Зав. № и АоРПИ собраны из папок Nextcloud: 2.Incoming control (1.Closed — подписан, 2.Open — не подписан), 1.RFI/CHENGDA, _Текст для поиска. «-» в столбце АоРПИ — акта в папке ВК нет.
A5: Поз. / тег | B5: Наименование (по СО) | C5: Тип, марка | D5: Ед. | E5: Кол-во по СО | F5: Заводской № (пусто — не найден) | G5: Найдено зав. №, шт | H5: Источник зав. № | I5: RFI | J5: АоРПИ (- если нет) | K5: Статус АоРПИ | L5: Итог | M5: Примечание | N5: Паспорт (TP) | O5: RFI по сводной 17.08.2026 | P5: АоРПИ по сводной 17.08.2026 | Q5: Замечание из сводной 17.08.2026 | R5: Сверка со сводной 17.08.2026
A6: 1.1 КРУ1, КРУ2 | B6: Ячейка КРУ 10 кВ, 630 А, 40 кА (в помещении ЩСН) | C6: КРУ-ЭЗ-10-40 (Энергозащита) | D6: компл. | E6: 2 | F6: 15007085; 15007086 | G6: 2 | H6: АоРПИ 880 | I6: 1448 | J6: 880-3120-ЭС3-ВК-ЧНД | K6: Не подписан | L6: =IF(F6="",IF(J6="-","Нет зав. №, нет АоРПИ","Нет зав. №"),IF(G6<E6,"Зав. № не все ("&G6&" из "&E6&")",IF(J6="-","Зав. № есть, АоРПИ нет",IF(K6="Подписан","ОК: зав. № + АоРПИ подписан","Зав. № есть, АоРПИ не подписан")))) | M6: В АоРПИ 880 второй номер записан как «150086» — вероятно 15007086, исправить | O6: CHENGDA-MU-IC-1448 | P6: 880-3120-ЭС3-ВК-ЧНД | R6: Совпадает
A7: 1.2 ТСН1, ТСН2 | B7: Трансформатор собственных нужд сухой 400 кВА, 10/0,4 кВ | C7: ТЛСЗ-400/10 УХЛ2 (СЗТТ) | D7: компл. | E7: 2 | F7: 5842; 5843 | G7: 2 | H7: АоРПИ 805 | I7: 1379 | J7: 805-3120-ЭС3-ВК-ЧНД | K7: Подписан | L7: =IF(F7="",IF(J7="-","Нет зав. №, нет АоРПИ","Нет зав. №"),IF(G7<E7,"Зав. № не все ("&G7&" из "&E7&")",IF(J7="-","Зав. № есть, АоРПИ нет",IF(K7="Подписан","ОК: зав. № + АоРПИ подписан","Зав. № есть, АоРПИ не подписан")))) | O7: CHENGDA-MU-IC-1379 | P7: 805-3120-ЭС3-ВК-ЧНД подписан | R7: Совпадает
A8: ЩСН | B8: Щит собственных нужд переменного тока 0,4 кВ, двухсекционный | C8: ЧЭТА | D8: компл. | E8: 1 | F8: 297-25 | G8: 1 | H8: АоРПИ 806 | I8: 1560-2, 1560 | J8: 806-3120-ЭС3-ВК-ЧНД | K8: Подписан | L8: =IF(F8="",IF(J8="-","Нет зав. №, нет АоРПИ","Нет зав. №"),IF(G8<E8,"Зав. № не все ("&G8&" из "&E8&")",IF(J8="-","Зав. № есть, АоРПИ нет",IF(K8="Подписан","ОК: зав. № + АоРПИ подписан","Зав. № есть, АоРПИ не подписан")))) | M8: В отклонённом RFI 1560-1 упаковочные листы на щит № 189-25 — уточнить | O8: CHENGDA-MU-IC-1560 | P8: 806-3120-ЭС3-ВК-ЧНД подписан | R8: RFI 1560 добавлен из сводной
A9: 1.3 ЩПТ | B9: Щит системы оперативного постоянного тока, двухсекционный | C9: ВОЛЬТАГ | D9: компл. | E9: 1 | F9: 25002 (ЩПТ №1); 25003 (ЩПТ №2) | G9: 2 | H9: RFI 1403 (паспорта) | I9: 1403 | J9: 816-3120-ЭС3-ВК-ЧНД | K9: Не подписан | L9: =IF(F9="",IF(J9="-","Нет зав. №, нет АоРПИ","Нет зав. №"),IF(G9<E9,"Зав. № не все ("&G9&" из "&E9&")",IF(J9="-","Зав. № есть, АоРПИ нет",IF(K9="Подписан","ОК: зав. № + АоРПИ подписан","Зав. № есть, АоРПИ не подписан")))) | M9: В АоРПИ 816 указан только «ЩПТ №2, зав. № 25002» — по паспортам №2 = 25003. ПНЗП-М: 24220, 24221 | O9: CHENGDA-MU-IC-1403 | P9: 816-3120-ЭС3-ВК-ЧНД | R9: Совпадает
A10: 1.4 | B10: Стеллаж аккумуляторный двухъярусный | C10: ACM1-2 (ВОЛЬТАГ) | D10: компл. | E10: 4 | G10: 0 | I10: 1403 | J10: 816-3120-ЭС3-ВК-ЧНД | K10: Не подписан | L10: =IF(F10="",IF(J10="-","Нет зав. №, нет АоРПИ","Нет зав. №"),IF(G10<E10,"Зав. № не все ("&G10&" из "&E10&")",IF(J10="-","Зав. № есть, АоРПИ нет",IF(K10="Подписан","ОК: зав. № + АоРПИ подписан","Зав. № есть, АоРПИ не подписан")))) | O10: CHENGDA-MU-IC-1403 | P10: 816-3120-ЭС3-ВК-ЧНД | R10: Совпадает
A11: 1.5 АБ1, АБ2 | B11: АКБ свинцово-кислотная 490 Ач, 104 эл. по 2 В | C11: OPzS 490 (ВОЛЬТАГ) | D11: компл. | E11: 2 | G11: 0 | I11: 1403 | J11: 816-3120-ЭС3-ВК-ЧНД | K11: Не подписан | L11: =IF(F11="",IF(J11="-","Нет зав. №, нет АоРПИ","Нет зав. №"),IF(G11<E11,"Зав. № не все ("&G11&" из "&E11&")",IF(J11="-","Зав. № есть, АоРПИ нет",IF(K11="Подписан","ОК: зав. № + АоРПИ подписан","Зав. № есть, АоРПИ не подписан")))) | M11: Зав. № батарей не найдены | O11: CHENGDA-MU-IC-1403 | P11: 816-3120-ЭС3-ВК-ЧНД | R11: Совпадает
A12: 1.6 (03L1201) | B12: Кран мостовой однобалочный подвесной двухпролётный 10 т | C12: FHU10-15-9 A3 | D12: компл. | E12: 1 | G12: 0 | I12: 1292-1, 1292 | J12: 526-3121-КЭ-ЧНД | K12: Не подписан | L12: =IF(F12="",IF(J12="-","Нет зав. №, нет АоРПИ","Нет зав. №"),IF(G12<E12,"Зав. № не все ("&G12&" из "&E12&")",IF(J12="-","Зав. № есть, АоРПИ нет",IF(K12="Подписан","ОК: зав. № + АоРПИ подписан","Зав. № есть, АоРПИ не подписан")))) | M12: В RFI/АоРПИ только индекс крана и тег 03L1201, зав. № нет | O12: CHENGDA-MU-IC-1292 | Q12: Документы отклонены. | R12: RFI 1292 добавлен из сводной; в сводной АоРПИ не указан, а в папке ВК есть: 526-3121-КЭ
A13: 1.7 | B13: Шкаф управления краном 400 В, 600х900х220 | C13: FEC22058-06 | D13: компл. | E13: 1 | G13: 0 | I13: 1292-1, 1292 | J13: 526-3121-КЭ-ЧНД | K13: Не подписан | L13: =IF(F13="",IF(J13="-","Нет зав. №, нет АоРПИ","Нет зав. №"),IF(G13<E13,"Зав. № не все ("&G13&" из "&E13&")",IF(J13="-","Зав. № есть, АоРПИ нет",IF(K13="Подписан","ОК: зав. № + АоРПИ подписан","Зав. № есть, АоРПИ не подписан")))) | O13: CHENGDA-MU-IC-1292 | Q13: Документов нет. | R13: RFI 1292 добавлен из сводной; в сводной АоРПИ не указан, а в папке ВК есть: 526-3121-КЭ
A14: 1.8 DCW1.1N, DCW1.2N | B14: Ящик с рубильником и штепсельным разъёмом, IP54 | C14: ЯВЗШ-31-100 УХЛ1 | D14: компл. | E14: 2 | G14: 0 | I14: 1541 | J14: - | K14: - | L14: =IF(F14="",IF(J14="-","Нет зав. №, нет АоРПИ","Нет зав. №"),IF(G14<E14,"Зав. № не все ("&G14&" из "&E14&")",IF(J14="-","Зав. № есть, АоРПИ нет",IF(K14="Подписан","ОК: зав. № + АоРПИ подписан","Зав. № есть, АоРПИ не подписан")))) | O14: CHENGDA-MU-IC-1541 | Q14: Документов нет, есть серьезные замечания к шкафам. | R14: RFI 1541 добавлен из сводной
A15: 1.9 DCW2.1N…DCW3.2N | B15: Ящик с рубильником и штепсельным разъёмом, IP31 | C15: ЯВЗШ-31-100 УХЛ4 | D15: компл. | E15: 6 | G15: 0 | I15: 1541 | J15: - | K15: - | L15: =IF(F15="",IF(J15="-","Нет зав. №, нет АоРПИ","Нет зав. №"),IF(G15<E15,"Зав. № не все ("&G15&" из "&E15&")",IF(J15="-","Зав. № есть, АоРПИ нет",IF(K15="Подписан","ОК: зав. № + АоРПИ подписан","Зав. № есть, АоРПИ не подписан")))) | O15: CHENGDA-MU-IC-1541 | Q15: Документов нет, есть серьезные замечания к шкафам. | R15: RFI 1541 добавлен из сводной
A16: 1.10 DC2.1-2.2N | B16: Вторичная силовая сборка DC2.1-2.2N | D16: компл. | E16: 1 | G16: 0 | I16: 1671 | J16: - | K16: - | L16: =IF(F16="",IF(J16="-","Нет зав. №, нет АоРПИ","Нет зав. №"),IF(G16<E16,"Зав. № не все ("&G16&" из "&E16&")",IF(J16="-","Зав. № есть, АоРПИ нет",IF(K16="Подписан","ОК: зав. № + АоРПИ подписан","Зав. № есть, АоРПИ не подписан")))) | O16: CHENGDA-MU-IC-1671 | R16: RFI 1671 добавлен из сводной
A17: 1.11 DC2.3N | B17: Вторичная силовая сборка DC2.3N | D17: компл. | E17: 1 | G17: 0 | I17: 1671 | J17: - | K17: - | L17: =IF(F17="",IF(J17="-","Нет зав. №, нет АоРПИ","Нет зав. №"),IF(G17<E17,"Зав. № не все ("&G17&" из "&E17&")",IF(J17="-","Зав. № есть, АоРПИ нет",IF(K17="Подписан","ОК: зав. № + АоРПИ подписан","Зав. № есть, АоРПИ не подписан")))) | O17: CHENGDA-MU-IC-1671 | R17: RFI 1671 добавлен из сводной
A18: 1.12 DC2.5N | B18: Вторичная силовая сборка отопления DC2.5N | D18: компл. | E18: 1 | G18: 0 | I18: 1671 | J18: - | K18: - | L18: =IF(F18="",IF(J18="-","Нет зав. №, нет АоРПИ","Нет зав. №"),IF(G18<E18,"Зав. № не все ("&G18&" из "&E18&")",IF(J18="-","Зав. № есть, АоРПИ нет",IF(K18="Подписан","ОК: зав. № + АоРПИ подписан","Зав. № есть, АоРПИ не подписан")))) | O18: CHENGDA-MU-IC-1671 | R18: RFI 1671 добавлен из сводной
A19: 1.13 DC2.6N | B19: Вторичная силовая сборка отопления DC2.6N | D19: компл. | E19: 1 | G19: 0 | I19: 1671 | J19: - | K19: - | L19: =IF(F19="",IF(J19="-","Нет зав. №, нет АоРПИ","Нет зав. №"),IF(G19<E19,"Зав. № не все ("&G19&" из "&E19&")",IF(J19="-","Зав. № есть, АоРПИ нет",IF(K19="Подписан","ОК: зав. № + АоРПИ подписан","Зав. № есть, АоРПИ не подписан")))) | O19: CHENGDA-MU-IC-1671 | R19: RFI 1671 добавлен из сводной
A20: 1.14 DC2.7N | B20: Вторичная силовая сборка кондиционирования DC2.7N | D20: компл. | E20: 1 | G20: 0 | I20: 1671 | J20: - | K20: - | L20: =IF(F20="",IF(J20="-","Нет зав. №, нет АоРПИ","Нет зав. №"),IF(G20<E20,"Зав. № не все ("&G20&" из "&E20&")",IF(J20="-","Зав. № есть, АоРПИ нет",IF(K20="Подписан","ОК: зав. № + АоРПИ подписан","Зав. № есть, АоРПИ не подписан")))) | O20: CHENGDA-MU-IC-1671 | R20: RFI 1671 добавлен из сводной
A21: 1.15 DC2.8N | B21: Вторичная силовая сборка вентиляции DC2.8N | D21: компл. | E21: 1 | G21: 0 | I21: 1671 | J21: - | K21: - | L21: =IF(F21="",IF(J21="-","Нет зав. №, нет АоРПИ","Нет зав. №"),IF(G21<E21,"Зав. № не все ("&G21&" из "&E21&")",IF(J21="-","Зав. № есть, АоРПИ нет",IF(K21="Подписан","ОК: зав. № + АоРПИ подписан","Зав. № есть, АоРПИ не подписан")))) | O21: CHENGDA-MU-IC-1671 | R21: RFI 1671 добавлен из сводной
A22: 1.16 DC2.9N | B22: Вторичная силовая сборка вентиляции DC2.9N | D22: компл. | E22: 1 | G22: 0 | I22: 1671 | J22: - | K22: - | L22: =IF(F22="",IF(J22="-","Нет зав. №, нет АоРПИ","Нет зав. №"),IF(G22<E22,"Зав. № не все ("&G22&" из "&E22&")",IF(J22="-","Зав. № есть, АоРПИ нет",IF(K22="Подписан","ОК: зав. № + АоРПИ подписан","Зав. № есть, АоРПИ не подписан")))) | O22: CHENGDA-MU-IC-1671 | R22: RFI 1671 добавлен из сводной
A23: 1.17 DC2.10N | B23: Вторичная силовая сборка вентиляции DC2.10N | D23: компл. | E23: 1 | G23: 0 | I23: 1671 | J23: - | K23: - | L23: =IF(F23="",IF(J23="-","Нет зав. №, нет АоРПИ","Нет зав. №"),IF(G23<E23,"Зав. № не все ("&G23&" из "&E23&")",IF(J23="-","Зав. № есть, АоРПИ нет",IF(K23="Подписан","ОК: зав. № + АоРПИ подписан","Зав. № есть, АоРПИ не подписан")))) | O23: CHENGDA-MU-IC-1671 | R23: RFI 1671 добавлен из сводной
A24: 1.18 DC2.11N | B24: Вторичная силовая сборка вентиляции DC2.11N | D24: компл. | E24: 1 | G24: 0 | I24: 1671 | J24: - | K24: - | L24: =IF(F24="",IF(J24="-","Нет зав. №, нет АоРПИ","Нет зав. №"),IF(G24<E24,"Зав. № не все ("&G24&" из "&E24&")",IF(J24="-","Зав. № есть, АоРПИ нет",IF(K24="Подписан","ОК: зав. № + АоРПИ подписан","Зав. № есть, АоРПИ не подписан")))) | O24: CHENGDA-MU-IC-1671 | R24: RFI 1671 добавлен из сводной
A25: 1.19 DC2.12N | B25: Вторичная силовая сборка вентиляции DC2.12N | D25: компл. | E25: 1 | G25: 0 | I25: 1671 | J25: - | K25: - | L25: =IF(F25="",IF(J25="-","Нет зав. №, нет АоРПИ","Нет зав. №"),IF(G25<E25,"Зав. № не все ("&G25&" из "&E25&")",IF(J25="-","Зав. № есть, АоРПИ нет",IF(K25="Подписан","ОК: зав. № + АоРПИ подписан","Зав. № есть, АоРПИ не подписан")))) | O25: CHENGDA-MU-IC-1671 | R25: RFI 1671 добавлен из сводной
A26: 1.20 DC2.13N | B26: Вторичная силовая сборка вентиляции DC2.13N | D26: компл. | E26: 1 | G26: 0 | I26: 1671 | J26: - | K26: - | L26: =IF(F26="",IF(J26="-","Нет зав. №, нет АоРПИ","Нет зав. №"),IF(G26<E26,"Зав. № не все ("&G26&" из "&E26&")",IF(J26="-","Зав. № есть, АоРПИ нет",IF(K26="Подписан","ОК: зав. № + АоРПИ подписан","Зав. № есть, АоРПИ не подписан")))) | O26: CHENGDA-MU-IC-1671 | R26: RFI 1671 добавлен из сводной
A27: 1.21 DC3.1N | B27: Вторичная силовая сборка DC3.1N (устан. в ЗРУ-10 кВ тит. 3123) | D27: компл. | E27: 1 | G27: 0 | I27: 1671 | J27: - | K27: - | L27: =IF(F27="",IF(J27="-","Нет зав. №, нет АоРПИ","Нет зав. №"),IF(G27<E27,"Зав. № не все ("&G27&" из "&E27&")",IF(J27="-","Зав. № есть, АоРПИ нет",IF(K27="Подписан","ОК: зав. № + АоРПИ подписан","Зав. № есть, АоРПИ не подписан")))) | O27: CHENGDA-MU-IC-1671 | R27: RFI 1671 добавлен из сводной
... A29: 1.23 DCM3.1N | B29: Панель противопожарных устройств (ППУ), в ЗРУ-10 кВ тит. 3123 | D29: компл. | E29: 1 | G29: 0 | I29: 1671 | J29: - | K29: - | L29: =IF(F29="",IF(J29="-","Нет зав. №, нет АоРПИ","Нет зав. №"),IF(G29<E29,"Зав. № не все ("&G29&" из "&E29&")",IF(J29="-","Зав. № есть, АоРПИ нет",IF(K29="Подписан","ОК: зав. № + АоРПИ подписан","Зав. № есть, АоРПИ не подписан")))) | O29: CHENGDA-MU-IC-1671 | R29: RFI 1671 добавлен из сводной
A30: 1.24 LCS | B30: Местная станция управления IP55, 400/230 В | C30: HLFX01-A2D1G | D30: компл. | E30: 8 | F30: 2601-00036; 2601-00037; 2601-00038; 2601-00039; 2601-00040; 2601-00041; 2601-00042; 2601-00043 | G30: 8 | H30: RFI 1610-2 | I30: 1610-2 | J30: 1080-3120-ЭС3-ВК-ЧНД | K30: Подписан | L30: =IF(F30="",IF(J30="-","Нет зав. №, нет АоРПИ","Нет зав. №"),IF(G30<E30,"Зав. № не все ("&G30&" из "&E30&")",IF(J30="-","Зав. № есть, АоРПИ нет",IF(K30="Подписан","ОК: зав. № + АоРПИ подписан","Зав. № есть, АоРПИ не подписан")))) | M30: В АоРПИ 1080 зав. № не указаны | O30: CHENGDA-MU-IC-1610-2 | P30: 1080-3120-ЭС3-ВК-ЧНД | Q30: Нет документов, приложенные документы не идентифицируют изделие. | R30: Совпадает
A31: 1.25 | B31: Выключатель одноклавишный IP20, 230 В, 10 А | C31: HLFX01-K1G | D31: шт | E31: 9 | F31: 2601-00047; 2601-00048; 2601-00049; 2601-00050; 2601-00051; 2601-00052; 2601-00053; 2601-00054; 2601-00055 | G31: 9 | H31: RFI 1610-2 | I31: 1610-2 | J31: 1080-3120-ЭС3-ВК-ЧНД | K31: Подписан | L31: =IF(F31="",IF(J31="-","Нет зав. №, нет АоРПИ","Нет зав. №"),IF(G31<E31,"Зав. № не все ("&G31&" из "&E31&")",IF(J31="-","Зав. № есть, АоРПИ нет",IF(K31="Подписан","ОК: зав. № + АоРПИ подписан","Зав. № есть, АоРПИ не подписан")))) | M31: В АоРПИ 1080 зав. № не указаны | O31: CHENGDA-MU-IC-1610-2 | P31: 1080-3120-ЭС3-ВК-ЧНД | Q31: Нет документов, приложенные документы не идентифицируют изделие. | R31: Совпадает
D32: Итого | E32: =SUM(E6:E31) | G32: =SUM(G6:G31)

Sheet 3120 ЭС4
A1: Титул 3120, раздел ЭС4 — оборудование (раздел «Оборудование» спецификации), заводские номера и АоРПИ
A2: СО: E19006-CXPP-3120-ЭС4.СО-001, ревизия 4А (.docm) — проверено 28.09.2026: СО ЭС4 новее 4А в папке РД нет
A3: Зав. № и АоРПИ собраны из папок Nextcloud: 2.Incoming control (1.Closed — подписан, 2.Open — не подписан), 1.RFI/CHENGDA, _Текст для поиска. «-» в столбце АоРПИ — акта в папке ВК нет.
A5: Поз. / тег | B5: Наименование (по СО) | C5: Тип, марка | D5: Ед. | E5: Кол-во по СО | F5: Заводской № (пусто — не найден) | G5: Найдено зав. №, шт | H5: Источник зав. № | I5: RFI | J5: АоРПИ (- если нет) | K5: Статус АоРПИ | L5: Итог | M5: Примечание | N5: Паспорт (TP) | O5: RFI по сводной 17.08.2026 | P5: АоРПИ по сводной 17.08.2026 | Q5: Замечание из сводной 17.08.2026 | R5: Сверка со сводной 17.08.2026
A6: 3121RC02, RC09 | B6: Дифзащита W1E, W2E с комплектом ступенчатых защит | C6: ШЭ2607 692-61Е2 (ЭКРА) | D6: шт | E6: 2 | F6: 35323; 35324 | G6: 2 | H6: АоРПИ 961 / RFI 1556 | I6: 1556 | J6: 961-3120-ЭС4-ВК-ЧНД | K6: Не подписан | L6: =IF(F6="",IF(J6="-","Нет зав. №, нет АоРПИ","Нет зав. №"),IF(G6<E6,"Зав. № не все ("&G6&" из "&E6&")",IF(J6="-","Зав. № есть, АоРПИ нет",IF(K6="Подписан","ОК: зав. № + АоРПИ подписан","Зав. № есть, АоРПИ не подписан")))) | O6: CHENGDA-MU-IC-1556 | P6: 961-3120-ЭС4-ВК-ЧНД | R6: Совпадает
A7: 3121RC03, RC10 | B7: Комплект ступенчатых защит W1E, W2E | C7: ШЭТ 220.08-0 Бреслер-0117.510 | D7: шт | E7: 2 | F7: 10589/1 (RC03); 10589/2 (RC10) | G7: 2 | H7: RFI 1556 | I7: 1556 | J7: 961-3120-ЭС4-ВК-ЧНД | K7: Не подписан | L7: =IF(F7="",IF(J7="-","Нет зав. №, нет АоРПИ","Нет зав. №"),IF(G7<E7,"Зав. № не все ("&G7&" из "&E7&")",IF(J7="-","Зав. № есть, АоРПИ нет",IF(K7="Подписан","ОК: зав. № + АоРПИ подписан","Зав. № есть, АоРПИ не подписан")))) | M7: В АоРПИ 961 поз. 2 номера не указаны | O7: CHENGDA-MU-IC-1556 | P7: 961-3120-ЭС4-ВК-ЧНД | R7: Совпадает
A8: 3121RC06, RC07, RC08 | B8: Автоматика управления выключателем Q2T1, Q2T2, QK1E | C8: ШЭТ 251.01-0 Бреслер-0117.600 | D8: шт | E8: 3 | F8: 10589/3 (RC06); 10589/5 (RC07); 10589/4 (RC08) | G8: 3 | H8: АоРПИ 961 / RFI 1556 | I8: 1556 | J8: 961-3120-ЭС4-ВК-ЧНД | K8: Не подписан | L8: =IF(F8="",IF(J8="-","Нет зав. №, нет АоРПИ","Нет зав. №"),IF(G8<E8,"Зав. № не все ("&G8&" из "&E8&")",IF(J8="-","Зав. № есть, АоРПИ нет",IF(K8="Подписан","ОК: зав. № + АоРПИ подписан","Зав. № есть, АоРПИ не подписан")))) | O8: CHENGDA-MU-IC-1556 | P8: 961-3120-ЭС4-ВК-ЧНД | R8: Совпадает
A9: 3121RC18, RC19, RC24, RC25 | B9: Комплект основных и резервных защит трансформатора Т-1, Т-2 | C9: ШЭТ 210.02-0 | D9: шт | E9: 4 | F9: 10589/6 (RC18); 10589/7 (RC19); 10589/11 (RC24); 10589/12 (RC25) | G9: 4 | H9: АоРПИ 961 / RFI 1556 | I9: 1556 | J9: 961-3120-ЭС4-ВК-ЧНД | K9: Не подписан | L9: =IF(F9="",IF(J9="-","Нет зав. №, нет АоРПИ","Нет зав. №"),IF(G9<E9,"Зав. № не все ("&G9&" из "&E9&")",IF(J9="-","Зав. № есть, АоРПИ нет",IF(K9="Подписан","ОК: зав. № + АоРПИ подписан","Зав. № есть, АоРПИ не подписан")))) | O9: CHENGDA-MU-IC-1556 | P9: 961-3120-ЭС4-ВК-ЧНД | R9: Совпадает
A10: 3121RC20, RC26 | B10: Защита ошиновки 220 кВ Т1, Т2 | C10: ШЭТ 440.02-0 | D10: шт | E10: 2 | F10: 10589/8 (RC20); 10589/13 (RC26) | G10: 2 | H10: АоРПИ 961 / RFI 1556 | I10: 1556 | J10: 961-3120-ЭС4-ВК-ЧНД | K10: Не подписан | L10: =IF(F10="",IF(J10="-","Нет зав. №, нет АоРПИ","Нет зав. №"),IF(G10<E10,"Зав. № не все ("&G10&" из "&E10&")",IF(J10="-","Зав. № есть, АоРПИ нет",IF(K10="Подписан","ОК: зав. № + АоРПИ подписан","Зав. № есть, АоРПИ не подписан")))) | O10: CHENGDA-MU-IC-1556 | P10: 961-3120-ЭС4-ВК-ЧНД | R10: Совпадает
A11: 3121RC21, RC27 | B11: Комплект ступенчатых защит 220 кВ Т-1, Т-2 (РЗАТ) | C11: ШЭТ 410.01-0 Бреслер-0117.730 | D11: шт | E11: 2 | F11: 10589/9 (RC21); 10589/14 (RC27) | G11: 2 | H11: АоРПИ 961 / RFI 1556 | I11: 1556 | J11: 961-3120-ЭС4-ВК-ЧНД | K11: Не подписан | L11: =IF(F11="",IF(J11="-","Нет зав. №, нет АоРПИ","Нет зав. №"),IF(G11<E11,"Зав. № не все ("&G11&" из "&E11&")",IF(J11="-","Зав. № есть, АоРПИ нет",IF(K11="Подписан","ОК: зав. № + АоРПИ подписан","Зав. № есть, АоРПИ не подписан")))) | O11: CHENGDA-MU-IC-1556 | P11: 961-3120-ЭС4-ВК-ЧНД | R11: Совпадает
A12: 3121RC22 | B12: Шкаф автоматики РПН Т-1, Т-2 | C12: Бреслер | D12: шт | E12: 1 | F12: 10589/10 | G12: 1 | H12: АоРПИ 961 / RFI 1556 | I12: 1556 | J12: 961-3120-ЭС4-ВК-ЧНД | K12: Не подписан | L12: =IF(F12="",IF(J12="-","Нет зав. №, нет АоРПИ","Нет зав. №"),IF(G12<E12,"Зав. № не все ("&G12&" из "&E12&")",IF(J12="-","Зав. № есть, АоРПИ нет",IF(K12="Подписан","ОК: зав. № + АоРПИ подписан","Зав. № есть, АоРПИ не подписан")))) | O12: CHENGDA-MU-IC-1556 | P12: 961-3120-ЭС4-ВК-ЧНД | R12: Совпадает
A13: 3121RC28, RC29 | B13: Шкаф ДЗШ 10 кВ K2К, К4К | C13: ШЭТ 140.01-0 Бреслер-0117.280 | D13: шт | E13: 2 | F13: 10589/15 (RC28); 10589/16 (RC29) | G13: 2 | H13: АоРПИ 961 / RFI 1556 | I13: 1556 | J13: 961-3120-ЭС4-ВК-ЧНД | K13: Не подписан | L13: =IF(F13="",IF(J13="-","Нет зав. №, нет АоРПИ","Нет зав. №"),IF(G13<E13,"Зав. № не все ("&G13&" из "&E13&")",IF(J13="-","Зав. № есть, АоРПИ нет",IF(K13="Подписан","ОК: зав. № + АоРПИ подписан","Зав. № есть, АоРПИ не подписан")))) | O13: CHENGDA-MU-IC-1556 | P13: 961-3120-ЭС4-ВК-ЧНД | R13: Совпадает
A14: 3121RC17 | B14: Шкаф регистратора аварийных событий (РАС) | C14: Бреслер-0117.010 | D14: шт | E14: 1 | F14: 10589/17 | G14: 1 | H14: АоРПИ 961 / RFI 1556 | I14: 1556 | J14: 961-3120-ЭС4-ВК-ЧНД | K14: Не подписан | L14: =IF(F14="",IF(J14="-","Нет зав. №, нет АоРПИ","Нет зав. №"),IF(G14<E14,"Зав. № не все ("&G14&" из "&E14&")",IF(J14="-","Зав. № есть, АоРПИ нет",IF(K14="Подписан","ОК: зав. № + АоРПИ подписан","Зав. № есть, АоРПИ не подписан")))) | O14: CHENGDA-MU-IC-1556 | P14: 961-3120-ЭС4-ВК-ЧНД | R14: Совпадает
